Workbook

Sheet Assumptions
A1: Local Loyalty — Assumptions (CAD)
A2: Legend: blue = input you can change; black = formula; blue on yellow = scenario override of Base. Non-Base columns follow Base unless overridden. Source/notes in column I. Mirrors model.py ASSUMPTIONS.
A4: Key | B4: Assumption | C4: Base | D4: Bear | E4: Base + reco gates | F4: Lean plan | G4: Bull | H4: Unit | I4: Source / note
A6: Scalar assumptions
A7: months | B7: Months | C7: 36 | D7: =$C$7 -> 36 | E7: =$C$7 -> 36 | F7: =$C$7 -> 36 | G7: =$C$7 -> 36 | H7: months | I7: Projection horizon (CSV + workbook)
A8: extended_months | B8: Extended months | C8: 60 | D8: =$C$8 -> 60 | E8: =$C$8 -> 60 | F8: =$C$8 -> 60 | G8: =$C$8 -> 60 | H8: months | I8: Extended run used ONLY to find break-even if it falls after month 36; keeps launching at the last quarter's pace
A9: starting_cash | B9: Starting cash | C9: 0 | D9: =$C$9 -> 0 | E9: =$C$9 -> 0 | F9: =$C$9 -> 0 | G9: =$C$9 -> 0 | H9: CAD | I9: Founder starts at $0; peak cash need = money required to bootstrap
A10: strip_potential_merchants | B10: Strip potential merchants | C10: 32 | D10: 24 | E10: =$C$10 -> 32 | F10: =$C$10 -> 32 | G10: 38 | H10: merchants/strip | I10: Assumption: 80+ storefronts (PRD strip criterion) x ~55% repeat-visit verticals x ~70% eventually sign
A11: activation_rate | B11: Activation rate | C11: 0.6 | D11: 0.5 | E11: =$C$11 -> 0.6 | F11: =$C$11 -> 0.6 | G11: 0.7 | H11: share of signed | I11: PRD success metric: 60% of signed reach 25 active members
A12: free_merchant_churn | B12: Free merchant churn | C12: 0.015 | D12: 0.025 | E12: =$C$12 -> 0.015 | F12: =$C$12 -> 0.015 | G12: 0.01 | H12: per month | I12: Assumption: business closures + drop-outs; free plan has no switching cost
A13: members_per_active_merchant | B13: Members per active merchant | C13: 75 | D13: 50 | E13: =$C$13 -> 75 | F13: =$C$13 -> 75 | G13: 100 | H13: active members | I13: PRD success metric (month 6 target)
A14: membership_fill_speed | B14: Membership fill speed | C14: 0.35 | D14: =$C$14 -> 0.35 | E14: =$C$14 -> 0.35 | F14: =$C$14 -> 0.35 | G14: =$C$14 -> 0.35 | H14: share of gap closed/month | I14: Assumption: ~6 months to reach target
A15: shops_per_customer | B15: Shops per customer | C15: 1.4 | D15: =$C$15 -> 1.4 | E15: =$C$15 -> 1.4 | F15: =$C$15 -> 1.4 | G15: =$C$15 -> 1.4 | H15: shops per active customer | I15: Assumption from PRD target: 30% of customers hold 2+ shops
A16: customer_churn | B16: Customer churn | C16: 0.04 | D16: =$C$16 -> 0.04 | E16: =$C$16 -> 0.04 | F16: =$C$16 -> 0.04 | G16: =$C$16 -> 0.04 | H16: per month | I16: Assumption: active customers lapsing (drives re-acquisition SMS)
A17: app_user_share | B17: App user share | C17: 0.35 | D17: =$C$17 -> 0.35 | E17: =$C$17 -> 0.35 | F17: =$C$17 -> 0.35 | G17: =$C$17 -> 0.35 | H17: share of active customers | I17: Assumption: most join via wallet pass/phone number and never open the app
A18: unlock_plus_active_merchants | B18: Unlock plus active merchants | C18: 150 | D18: =$C$18 -> 150 | E18: 100 | F18: 100 | G18: =$C$18 -> 150 | H18: active merchants | I18: plans.ts unlockAtMerchants for Plus features
A19: plus_features_ready_month | B19: Plus features ready month | C19: 10 | D19: =$C$19 -> 10 | E19: =$C$19 -> 10 | F19: =$C$19 -> 10 | G19: =$C$19 -> 10 | H19: model month | I19: Assumption: Phase 2 build done Aug 2027 (PRD months 7-12)
A20: unlock_pro_active_merchants | B20: Unlock pro active merchants | C20: 150 | D20: =$C$20 -> 150 | E20: 40 | F20: 40 | G20: =$C$20 -> 150 | H20: active merchants | I20: plans.ts unlockAtMerchants for Pro features
A21: pro_features_ready_month | B21: Pro features ready month | C21: 10 | D21: =$C$21 -> 10 | E21: 8 | F21: 8 | G21: =$C$21 -> 10 | H21: model month | I21: Assumption: Phase 2 build done Aug 2027 (PRD months 7-12)
A22: unlock_bia_active_merchants | B22: Unlock bia active merchants | C22: 100 | D22: =$C$22 -> 100 | E22: =$C$22 -> 100 | F22: =$C$22 -> 100 | G22: =$C$22 -> 100 | H22: active merchants | I22: plans.ts campaigns.neighbourhood unlockAtMerchants
A23: unlock_ads_active_merchants | B23: Unlock ads active merchants | C23: 400 | D23: =$C$23 -> 400 | E23: 300 | F23: 300 | G23: =$C$23 -> 400 | H23: active merchants | I23: plans.ts ads.* unlockAtMerchants
A24: ads_ready_month | B24: Ads ready month | C24: 18 | D24: =$C$24 -> 18 | E24: =$C$24 -> 18 | F24: =$C$24 -> 18 | G24: =$C$24 -> 18 | H24: model month | I24: Assumption: ad tooling built by Apr 2028
A25: mix_food_bev | B25: Mix food bev | C25: 0.35 | D25: =$C$25 -> 0.35 | E25: =$C$25 -> 0.35 | F25: =$C$25 -> 0.35 | G25: =$C$25 -> 0.35 | H25: share of merchants | I25: Assumption: daily-visit anchors of a strip
A26: mix_retail | B26: Mix retail | C26: 0.25 | D26: =$C$26 -> 0.25 | E26: =$C$26 -> 0.25 | F26: =$C$26 -> 0.25 | G26: =$C$26 -> 0.25 | H26: share of merchants | I26: Assumption
A27: mix_repair_auto | B27: Mix repair auto | C27: 0.2 | D27: =$C$27 -> 0.2 | E27: =$C$27 -> 0.2 | F27: =$C$27 -> 0.2 | G27: =$C$27 -> 0.2 | H27: share of merchants | I27: Assumption: PRD says lead with repair/auto for revenue
A28: mix_personal_services | B28: Mix personal services | C28: 0.12 | D28: =$C$28 -> 0.12 | E28: =$C$28 -> 0.12 | F28: =$C$28 -> 0.12 | G28: =$C$28 -> 0.12 | H28: share of merchants | I28: Assumption
A29: mix_pharmacy | B29: Mix pharmacy | C29: 0.08 | D29: =$C$29 -> 0.08 | E29: =$C$29 -> 0.08 | F29: =$C$29 -> 0.08 | G29: =$C$29 -> 0.08 | H29: share of merchants | I29: Assumption
A30: conv12_food_bev | B30: Conv12 food bev | C30: 0.2 | D30: =$C$30 -> 0.2 | E30: =$C$30 -> 0.2 | F30: =$C$30 -> 0.2 | G30: =$C$30 -> 0.2 | H30: 12-month conversion | I30: Assumption: order-ahead/pickup pain is moderate
A31: conv12_retail | B31: Conv12 retail | C31: 0.12 | D31: =$C$31 -> 0.12 | E31: =$C$31 -> 0.12 | F31: =$C$31 -> 0.12 | G31: =$C$31 -> 0.12 | H31: 12-month conversion | I31: Assumption: SMS + push promos only
A32: conv12_repair_auto | B32: Conv12 repair auto | C32: 0.4 | D32: =$C$32 -> 0.4 | E32: =$C$32 -> 0.4 | F32: =$C$32 -> 0.4 | G32: =$C$32 -> 0.4 | H32: 12-month conversion | I32: Assumption: quote approval/deposits replace phone tag (validate with $100 pilot deposits, PRD)
A33: conv12_personal_services | B33: Conv12 personal services | C33: 0.15 | D33: =$C$33 -> 0.15 | E33: =$C$33 -> 0.15 | F33: =$C$33 -> 0.15 | G33: =$C$33 -> 0.15 | H33: 12-month conversion | I33: Assumption
A34: conv12_pharmacy | B34: Conv12 pharmacy | C34: 0.05 | D34: =$C$34 -> 0.05 | E34: =$C$34 -> 0.05 | F34: =$C$34 -> 0.05 | G34: =$C$34 -> 0.05 | H34: 12-month conversion | I34: Assumption: limited by OCP inducement rules
A35: pro_share_food_bev | B35: Pro share food bev | C35: 0.05 | D35: =$C$35 -> 0.05 | E35: =$C$35 -> 0.05 | F35: =$C$35 -> 0.05 | G35: =$C$35 -> 0.05 | H35: share Pro | I35: Assumption
A36: pro_share_retail | B36: Pro share retail | C36: 0.05 | D36: =$C$36 -> 0.05 | E36: =$C$36 -> 0.05 | F36: =$C$36 -> 0.05 | G36: =$C$36 -> 0.05 | H36: share Pro | I36: Assumption
A37: pro_share_repair_auto | B37: Pro share repair auto | C37: 0.85 | D37: =$C$37 -> 0.85 | E37: =$C$37 -> 0.85 | F37: =$C$37 -> 0.85 | G37: =$C$37 -> 0.85 | H37: share Pro | I37: Assumption: service tickets, quotes, invoices are Pro
A38: pro_share_personal_services | B38: Pro share personal services | C38: 0.3 | D38: =$C$38 -> 0.3 | E38: =$C$38 -> 0.3 | F38: =$C$38 -> 0.3 | G38: =$C$38 -> 0.3 | H38: share Pro | I38: Assumption: drop-off scheduling/permissions
A39: pro_share_pharmacy | B39: Pro share pharmacy | C39: 0 | D39: =$C$39 -> 0 | E39: =$C$39 -> 0 | F39: =$C$39 -> 0 | G39: =$C$39 -> 0 | H39: share Pro | I39: Assumption
A40: conversion_multiplier | B40: Conversion multiplier | C40: 1 | D40: 0.6 | E40: =$C$40 -> 1 | F40: =$C$40 -> 1 | G40: 1.3 | H40: x | I40: Scenario/sensitivity lever on all conversion rates
A41: paid_churn | B41: Paid churn | C41: 0.03 | D41: 0.045 | E41: =$C$41 -> 0.03 | F41: =$C$41 -> 0.03 | G41: 0.0225 | H41: per month | I41: PRD assumption (~33-month life); churned payers drop back to Free
A42: price_plus | B42: Price plus | C42: 39 | D42: =$C$42 -> 39 | E42: =$C$42 -> 39 | F42: =$C$42 -> 39 | G42: =$C$42 -> 39 | H42: CAD/month | I42: plans.ts PLANS.plus.priceCents = 3900
...

Sheet Scenarios
A1: Scenarios — live KPIs from each monthly sheet (CAD)
A2: Scenario inputs are the columns of the Assumptions sheet; overrides are highlighted there.
A4: Metric | B4: Base | C4: Bear | D4: Base + reco gates | E4: Lean plan | F4: Bull
A5: Break-even month (36m) | B5: =Monthly!$C$85 -> none | C5: =Monthly_Bear!$C$85 -> none | D5: =Monthly_RecoGates!$C$85 -> none | E5: =Monthly_Lean!$C$85 -> none | F5: =Monthly_Bull!$C$85 -> none
A6: Break-even month (60m run) | B6: =Monthly!$C$86 -> 60 | C6: =Monthly_Bear!$C$86 -> none | D6: =Monthly_RecoGates!$C$86 -> 60 | E6: =Monthly_Lean!$C$86 -> 39 | F6: =Monthly_Bull!$C$86 -> 46
A7: First EBITDA-positive month | B7: =Monthly!$C$87 -> none | C7: =Monthly_Bear!$C$87 -> none | D7: =Monthly_RecoGates!$C$87 -> none | E7: =Monthly_Lean!$C$87 -> none | F7: =Monthly_Bull!$C$87 -> none
A8: Peak cash need, months 1-36 | B8: =Monthly!$C$88 -> 322991.1 | C8: =Monthly_Bear!$C$88 -> 305899.55 | D8: =Monthly_RecoGates!$C$88 -> 310918.03 | E8: =Monthly_Lean!$C$88 -> 197411.15 | F8: =Monthly_Bull!$C$88 -> 297222.86
A9: Cash needed to reach break-even (60m) | B9: =Monthly!$C$90 -> 420715.24 | C9: =Monthly_Bear!$C$90 -> 545418.1 | D9: =Monthly_RecoGates!$C$90 -> 401426.7 | E9: =Monthly_Lean!$C$90 -> 199397.64 | F9: =Monthly_Bull!$C$90 -> 315810.81
A10: Cash trough month (36m) | B10: =Monthly!$C$89 -> 36 | C10: =Monthly_Bear!$C$89 -> 36 | D10: =Monthly_RecoGates!$C$89 -> 36 | E10: =Monthly_Lean!$C$89 -> 36 | F10: =Monthly_Bull!$C$89 -> 36
A11: Plus unlock month | B11: =Monthly!$C$91 -> 22 | C11: =Monthly_Bear!$C$91 -> 36 | D11: =Monthly_RecoGates!$C$91 -> 18 | E11: =Monthly_Lean!$C$91 -> 16 | F11: =Monthly_Bull!$C$91 -> 16
A12: Pro unlock month | B12: =Monthly!$C$92 -> 22 | C12: =Monthly_Bear!$C$92 -> 36 | D12: =Monthly_RecoGates!$C$92 -> 12 | E12: =Monthly_Lean!$C$92 -> 11 | F12: =Monthly_Bull!$C$92 -> 16
A13: BIA unlock month | B13: =Monthly!$C$93 -> 18 | C13: =Monthly_Bear!$C$93 -> 29 | D13: =Monthly_RecoGates!$C$93 -> 18 | E13: =Monthly_Lean!$C$93 -> 16 | F13: =Monthly_Bull!$C$93 -> 14
A14: Ads unlock month | B14: =Monthly!$C$94 -> none | C14: =Monthly_Bear!$C$94 -> none | D14: =Monthly_RecoGates!$C$94 -> 31 | E14: =Monthly_Lean!$C$94 -> 27 | F14: =Monthly_Bull!$C$94 -> 26
A15: Month-36 active merchants | B15: =Monthly!$C$95 -> 398.76048 | C15: =Monthly_Bear!$C$95 -> 155.61935 | D15: =Monthly_RecoGates!$C$95 -> 398.76048 | E15: =Monthly_Lean!$C$95 -> 546.01289 | F15: =Monthly_Bull!$C$95 -> 797.3703
A16: Month-36 paying merchants | B16: =Monthly!$C$96 -> 58.104389 | C16: =Monthly_Bear!$C$96 -> 1.8102727 | D16: =Monthly_RecoGates!$C$96 -> 62.541469 | E16: =Monthly_Lean!$C$96 -> 86.712948 | F16: =Monthly_Bull!$C$96 -> 162.16383
A17: Month-36 active customers | B17: =Monthly!$C$97 -> 19474.991 | C17: =Monthly_Bear!$C$97 -> 5041.5366 | D17: =Monthly_RecoGates!$C$97 -> 19474.991 | E17: =Monthly_Lean!$C$97 -> 26607.87 | F17: =Monthly_Bull!$C$97 -> 51684.321
A18: Month-36 revenue | B18: =Monthly!$C$98 -> 8117.5131 | C18: =Monthly_Bear!$C$98 -> 1434.5128 | D18: =Monthly_RecoGates!$C$98 -> 10333.828 | E18: =Monthly_Lean!$C$98 -> 19693.578 | F18: =Monthly_Bull!$C$98 -> 24766.787
A19: Month-36 EBITDA | B19: =Monthly!$C$99 -> -9622.449 | C19: =Monthly_Bear!$C$99 -> -10902.903 | D19: =Monthly_RecoGates!$C$99 -> -7711.5074 | E19: =Monthly_Lean!$C$99 -> -1648.6465 | F19: =Monthly_Bull!$C$99 -> -3785.9249
A20: Year-1 revenue | B20: =Monthly!$C$100 -> 0 | C20: =Monthly_Bear!$C$100 -> 0 | D20: =Monthly_RecoGates!$C$100 -> 35.16651 | E20: =Monthly_Lean!$C$100 -> 116.79014 | F20: =Monthly_Bull!$C$100 -> 0
A21: Year-2 revenue | B21: =Monthly!$C$101 -> 8877.7828 | C21: =Monthly_Bear!$C$101 -> 0 | D21: =Monthly_RecoGates!$C$101 -> 14442.006 | E21: =Monthly_Lean!$C$101 -> 34541.848 | F21: =Monthly_Bull!$C$101 -> 36148.209
A22: Year-3 revenue | B22: =Monthly!$C$102 -> 62747.457 | C22: =Monthly_Bear!$C$102 -> 8184.5128 | D22: =Monthly_RecoGates!$C$102 -> 74485.46 | E22: =Monthly_Lean!$C$102 -> 156099.47 | F22: =Monthly_Bull!$C$102 -> 193437.7
A23: Year-1 EBITDA | B23: =Monthly!$C$103 -> -84348.511 | C23: =Monthly_Bear!$C$103 -> -78847.286 | D23: =Monthly_RecoGates!$C$103 -> -84344.415 | E23: =Monthly_Lean!$C$103 -> -63351.367 | F23: =Monthly_Bull!$C$103 -> -88986.255
A24: Year-2 EBITDA | B24: =Monthly!$C$104 -> -113012.32 | C24: =Monthly_Bear!$C$104 -> -99702.923 | D24: =Monthly_RecoGates!$C$104 -> -110057.24 | E24: =Monthly_Lean!$C$104 -> -82521.603 | F24: =Monthly_Bull!$C$104 -> -122340.52
A25: Year-3 EBITDA | B25: =Monthly!$C$105 -> -125630.27 | C25: =Monthly_Bear!$C$105 -> -127349.34 | D25: =Monthly_RecoGates!$C$105 -> -116516.37 | E25: =Monthly_Lean!$C$105 -> -51538.178 | F25: =Monthly_Bull!$C$105 -> -85896.087
A27: LTV/CAC (from Unit Economics) | B27: ='Unit Economics'!B22 -> 2.6460144 | C27: ='Unit Economics'!C22 -> 0.78088083 | D27: ='Unit Economics'!D22 -> 2.6460144 | E27: ='Unit Economics'!E22 -> 2.6460144 | F27: ='Unit Economics'!F22 -> 5.5152978
A28: Payback months (from Unit Economics) | B28: ='Unit Economics'!B23 -> 12.597563 | C28: ='Unit Economics'!C23 -> 28.457892 | D28: ='Unit Economics'!D23 -> 12.597563 | E28: ='Unit Economics'!E23 -> 12.597563 | F28: ='Unit Economics'!F23 -> 8.0583943

Sheet Unit Economics
A1: Unit economics — steady state, per merchant per month (CAD)
A2: Live formulas on the Assumptions sheet. CAC per paying merchant loads all acquisition spend on free merchants onto the ones that convert within 24 months.
A4: Metric | B4: Base | C4: Bear | D4: Base + reco gates | E4: Lean plan | F4: Bull
A5: Unique customers per active merchant | B5: =Assumptions!$C$13/Assumptions!$C$15 -> 53.571429 | C5: =Assumptions!$D$13/Assumptions!$D$15 -> 35.714286 | D5: =Assumptions!$E$13/Assumptions!$E$15 -> 53.571429 | E5: =Assumptions!$F$13/Assumptions!$F$15 -> 53.571429 | F5: =Assumptions!$G$13/Assumptions!$G$15 -> 71.428571
A6: Free merchant: infra + support | B6: =Assumptions!$C$60+Assumptions!$C$63/60*Assumptions!$C$62 -> 3.0833333 | C6: =Assumptions!$D$60+Assumptions!$D$63/60*Assumptions!$D$62 -> 3.0833333 | D6: =Assumptions!$E$60+Assumptions!$E$63/60*Assumptions!$E$62 -> 3.0833333 | E6: =Assumptions!$F$60+Assumptions!$F$63/60*Assumptions!$F$62 -> 3.0833333 | F6: =Assumptions!$G$60+Assumptions!$G$63/60*Assumptions!$G$62 -> 3.0833333
A7: Free merchant: its customers (infra, SMS, perks) | B7: =B5*(Assumptions!$C$61+Assumptions!$C$59*Assumptions!$C$55+Assumptions!$C$16*(Assumptions!$C$58*Assumptions!$C$55+Assumptions!$C$65*Assumptions!$C$66*Assumptions!$C$67)) -> 1.5385714 | C7: =C5*(Assumptions!$D$61+Assumptions!$D$59*Assumptions!$D$55+Assumptions!$D$16*(Assumptions!$D$58*Assumptions!$D$55+Assumptions!$D$65*Assumptions!$D$66*Assumptions!$D$67)) -> 1.0257143 | D7: =D5*(Assumptions!$E$61+Assumptions!$E$59*Assumptions!$E$55+Assumptions!$E$16*(Assumptions!$E$58*Assumptions!$E$55+Assumptions!$E$65*Assumptions!$E$66*Assumptions!$E$67)) -> 1.5385714 | E7: =E5*(Assumptions!$F$61+Assumptions!$F$59*Assumptions!$F$55+Assumptions!$F$16*(Assumptions!$F$58*Assumptions!$F$55+Assumptions!$F$65*Assumptions!$F$66*Assumptions!$F$67)) -> 1.5385714 | F7: =F5*(Assumptions!$G$61+Assumptions!$G$59*Assumptions!$G$55+Assumptions!$G$16*(Assumptions!$G$58*Assumptions!$G$55+Assumptions!$G$65*Assumptions!$G$66*Assumptions!$G$67)) -> 2.0514286
A8: Cost of a free active merchant / month | B8: =B6+B7 -> 4.6219048 | C8: =C6+C7 -> 4.1090476 | D8: =D6+D7 -> 4.6219048 | E8: =E6+E7 -> 4.6219048 | F8: =F6+F7 -> 5.1347619
A9: Free→paid within 24 months (mix-weighted) | B9: =Assumptions!$C$25*(1-(1-((1-(1-Assumptions!$C$30)^(1/12))*Assumptions!$C$40))^24)+Assumptions!$C$26*(1-(1-((1-(1-Assumptions!$C$31)^(1/12))*Assumptions!$C$40))^24)+Assumptions!$C$27*(1-(1-((1-(1-Assumptions!$C$32)^(1/12))*Assumptions!$C$40))^24)+Assumptions!$C$28*(1-(1-((1-(1-Assumptions!$C$33)^(1/12))*Assumptions!$C$40))^24)+Assumptions!$C$29*(1-(1-((1-(1-Assumptions!$C$34)^(1/12))*Assumptions!$C$40))^24) -> 0.3515 | C9: =Assumptions!$D$25*(1-(1-((1-(1-Assumptions!$D$30)^(1/12))*Assumptions!$D$40))^24)+Assumptions!$D$26*(1-(1-((1-(1-Assumptions!$D$31)^(1/12))*Assumptions!$D$40))^24)+Assumptions!$D$27*(1-(1-((1-(1-Assumptions!$D$32)^(1/12))*Assumptions!$D$40))^24)+Assumptions!$D$28*(1-(1-((1-(1-Assumptions!$D$33)^(1/12))*Assumptions!$D$40))^24)+Assumptions!$D$29*(1-(1-((1-(1-Assumptions!$D$34)^(1/12))*Assumptions!$D$40))^24) -> 0.23450483 | D9: =Assumptions!$E$25*(1-(1-((1-(1-Assumptions!$E$30)^(1/12))*Assumptions!$E$40))^24)+Assumptions!$E$26*(1-(1-((1-(1-Assumptions!$E$31)^(1/12))*Assumptions!$E$40))^24)+Assumptions!$E$27*(1-(1-((1-(1-Assumptions!$E$32)^(1/12))*Assumptions!$E$40))^24)+Assumptions!$E$28*(1-(1-((1-(1-Assumptions!$E$33)^(1/12))*Assumptions!$E$40))^24)+Assumptions!$E$29*(1-(1-((1-(1-Assumptions!$E$34)^(1/12))*Assumptions!$E$40))^24) -> 0.3515 | E9: =Assumptions!$F$25*(1-(1-((1-(1-Assumptions!$F$30)^(1/12))*Assumptions!$F$40))^24)+Assumptions!$F$26*(1-(1-((1-(1-Assumptions!$F$31)^(1/12))*Assumptions!$F$40))^24)+Assumptions!$F$27*(1-(1-((1-(1-Assumptions!$F$32)^(1/12))*Assumptions!$F$40))^24)+Assumptions!$F$28*(1-(1-((1-(1-Assumptions!$F$33)^(1/12))*Assumptions!$F$40))^24)+Assumptions!$F$29*(1-(1-((1-(1-Assumptions!$F$34)^(1/12))*Assumptions!$F$40))^24) -> 0.3515 | F9: =Assumptions!$G$25*(1-(1-((1-(1-Assumptions!$G$30)^(1/12))*Assumptions!$G$40))^24)+Assumptions!$G$26*(1-(1-((1-(1-Assumptions!$G$31)^(1/12))*Assumptions!$G$40))^24)+Assumptions!$G$27*(1-(1-((1-(1-Assumptions!$G$32)^(1/12))*Assumptions!$G$40))^24)+Assumptions!$G$28*(1-(1-((1-(1-Assumptions!$G$33)^(1/12))*Assumptions!$G$40))^24)+Assumptions!$G$29*(1-(1-((1-(1-Assumptions!$G$34)^(1/12))*Assumptions!$G$40))^24) -> 0.42406075
A10: Share of payers on Pro | B10: =(Assumptions!$C$25*(1-(1-((1-(1-Assumptions!$C$30)^(1/12))*Assumptions!$C$40))^24)*Assumptions!$C$35+Assumptions!$C$26*(1-(1-((1-(1-Assumptions!$C$31)^(1/12))*Assumptions!$C$40))^24)*Assumptions!$C$36+Assumptions!$C$27*(1-(1-((1-(1-Assumptions!$C$32)^(1/12))*Assumptions!$C$40))^24)*Assumptions!$C$37+Assumptions!$C$28*(1-(1-((1-(1-Assumptions!$C$33)^(1/12))*Assumptions!$C$40))^24)*Assumptions!$C$38+Assumptions!$C$29*(1-(1-((1-(1-Assumptions!$C$34)^(1/12))*Assumptions!$C$40))^24)*Assumptions!$C$39)/B9 -> 0.36389758 | C10: =(Assumptions!$D$25*(1-(1-((1-(1-Assumptions!$D$30)^(1/12))*Assumptions!$D$40))^24)*Assumptions!$D$35+Assumptions!$D$26*(1-(1-((1-(1-Assumptions!$D$31)^(1/12))*Assumptions!$D$40))^24)*Assumptions!$D$36+Assumptions!$D$27*(1-(1-((1-(1-Assumptions!$D$32)^(1/12))*Assumptions!$D$40))^24)*Assumptions!$D$37+Assumptions!$D$28*(1-(1-((1-(1-Assumptions!$D$33)^(1/12))*Assumptions!$D$40))^24)*Assumptions!$D$38+Assumptions!$D$29*(1-(1-((1-(1-Assumptions!$D$34)^(1/12))*Assumptions!$D$40))^24)*Assumptions!$D$39)/C9 -> 0.38232818 | D10: =(Assumptions!$E$25*(1-(1-((1-(1-Assumptions!$E$30)^(1/12))*Assumptions!$E$40))^24)*Assumptions!$E$35+Assumptions!$E$26*(1-(1-((1-(1-Assumptions!$E$31)^(1/12))*Assumptions!$E$40))^24)*Assumptions!$E$36+Assumptions!$E$27*(1-(1-((1-(1-Assumptions!$E$32)^(1/12))*Assumptions!$E$40))^24)*Assumptions!$E$37+Assumptions!$E$28*(1-(1-((1-(1-Assumptions!$E$33)^(1/12))*Assumptions!$E$40))^24)*Assumptions!$E$38+Assumptions!$E$29*(1-(1-((1-(1-Assumptions!$E$34)^(1/12))*Assumptions!$E$40))^24)*Assumptions!$E$39)/D9 -> 0.36389758 | E10: =(Assumptions!$F$25*(1-(1-((1-(1-Assumptions!$F$30)^(1/12))*Assumptions!$F$40))^24)*Assumptions!$F$35+Assumptions!$F$26*(1-(1-((1-(1-Assumptions!$F$31)^(1/12))*Assumptions!$F$40))^24)*Assumptions!$F$36+Assumptions!$F$27*(1-(1-((1-(1-Assumptions!$F$32)^(1/12))*Assumptions!$F$40))^24)*Assumptions!$F$37+Assumptions!$F$28*(1-(1-((1-(1-Assumptions!$F$33)^(1/12))*Assumptions!$F$40))^24)*Assumptions!$F$38+Assumptions!$F$29*(1-(1-((1-(1-Assumptions!$F$34)^(1/12))*Assumptions!$F$40))^24)*Assumptions!$F$39)/E9 -> 0.36389758 | F10: =(Assumptions!$G$25*(1-(1-((1-(1-Assumptions!$G$30)^(1/12))*Assumptions!$G$40))^24)*Assumptions!$G$35+Assumptions!$G$26*(1-(1-((1-(1-Assumptions!$G$31)^(1/12))*Assumptions!$G$40))^24)*Assumptions!$G$36+Assumptions!$G$27*(1-(1-((1-(1-Assumptions!$G$32)^(1/12))*Assumptions!$G$40))^24)*Assumptions!$G$37+Assumptions!$G$28*(1-(1-((1-(1-Assumptions!$G$33)^(1/12))*Assumptions!$G$40))^24)*Assumptions!$G$38+Assumptions!$G$29*(1-(1-((1-(1-Assumptions!$G$34)^(1/12))*Assumptions!$G$40))^24)*Assumptions!$G$39)/F9 -> 0.35143675
A11: Subscription ARPU (blended Plus/Pro) | B11: =Assumptions!$C$42*(1-B10)+Assumptions!$C$43*B10 -> 53.555903 | C11: =Assumptions!$D$42*(1-C10)+Assumptions!$D$43*C10 -> 54.293127 | D11: =Assumptions!$E$42*(1-D10)+Assumptions!$E$43*D10 -> 53.555903 | E11: =Assumptions!$F$42*(1-E10)+Assumptions!$F$43*E10 -> 53.555903 | F11: =Assumptions!$G$42*(1-F10)+Assumptions!$G$43*F10 -> 53.05747
A12: Payments margin net of Stripe Connect | B12: =Assumptions!$C$45*((Assumptions!$C$46*(1-B10)+Assumptions!$C$47*B10)*(Assumptions!$C$44-Assumptions!$C$51)-Assumptions!$C$52) -> 10.120925 | C12: =Assumptions!$D$45*((Assumptions!$D$46*(1-C10)+Assumptions!$D$47*C10)*(Assumptions!$D$44-Assumptions!$D$51)-Assumptions!$D$52) -> 6.8762973 | D12: =Assumptions!$E$45*((Assumptions!$E$46*(1-D10)+Assumptions!$E$47*D10)*(Assumptions!$E$44-Assumptions!$E$51)-Assumptions!$E$52) -> 10.120925 | E12: =Assumptions!$F$45*((Assumptions!$F$46*(1-E10)+Assumptions!$F$47*E10)*(Assumptions!$F$44-Assumptions!$F$51)-Assumptions!$F$52) -> 10.120925 | F12: =Assumptions!$G$45*((Assumptions!$G$46*(1-F10)+Assumptions!$G$47*F10)*(Assumptions!$G$44-Assumptions!$G$51)-Assumptions!$G$52) -> 12.487607
A13: SMS cost (included allowance used) | B13: =(Assumptions!$C$56*(1-B10)+Assumptions!$C$57*B10)*Assumptions!$C$55 -> 11.403448 | C13: =(Assumptions!$D$56*(1-C10)+Assumptions!$D$57*C10)*Assumptions!$D$55 -> 11.646732 | D13: =(Assumptions!$E$56*(1-D10)+Assumptions!$E$57*D10)*Assumptions!$E$55 -> 11.403448 | E13: =(Assumptions!$F$56*(1-E10)+Assumptions!$F$57*E10)*Assumptions!$F$55 -> 11.403448 | F13: =(Assumptions!$G$56*(1-F10)+Assumptions!$G$57*F10)*Assumptions!$G$55 -> 11.238965
A14: Subscription billing fees | B14: =B11*Assumptions!$C$53+Assumptions!$C$54 -> 2.1209007 | C14: =C11*Assumptions!$D$53+Assumptions!$D$54 -> 2.1459663 | D14: =D11*Assumptions!$E$53+Assumptions!$E$54 -> 2.1209007 | E14: =E11*Assumptions!$F$53+Assumptions!$F$54 -> 2.1209007 | F14: =F11*Assumptions!$G$53+Assumptions!$G$54 -> 2.103954
A15: Extra support for paid features | B15: =Assumptions!$C$64/60*Assumptions!$C$62 -> 6.25 | C15: =Assumptions!$D$64/60*Assumptions!$D$62 -> 6.25 | D15: =Assumptions!$E$64/60*Assumptions!$E$62 -> 6.25 | E15: =Assumptions!$F$64/60*Assumptions!$F$62 -> 6.25 | F15: =Assumptions!$G$64/60*Assumptions!$G$62 -> 6.25
A16: Contribution per paying merchant / month | B16: =B11+B12-B13-B14-B15 -> 43.902479 | C16: =C11+C12-C13-C14-C15 -> 41.126726 | D16: =D11+D12-D13-D14-D15 -> 43.902479 | E16: =E11+E12-E13-E14-E15 -> 43.902479 | F16: =F11+F12-F13-F14-F15 -> 45.952158
A17: CAC per signed merchant | B17: =Assumptions!$C$91*(Assumptions!$C$86*Assumptions!$C$83*(1+Assumptions!$C$85)+Assumptions!$C$11*Assumptions!$C$87*(1+Assumptions!$C$85)+Assumptions!$C$88+Assumptions!$C$89/Assumptions!$C$10) -> 106.09625 | C17: =Assumptions!$D$91*(Assumptions!$D$86*Assumptions!$D$83*(1+Assumptions!$D$85)+Assumptions!$D$11*Assumptions!$D$87*(1+Assumptions!$D$85)+Assumptions!$D$88+Assumptions!$D$89/Assumptions!$D$10) -> 131.36725 | D17: =Assumptions!$E$91*(Assumptions!$E$86*Assumptions!$E$83*(1+Assumptions!$E$85)+Assumptions!$E$11*Assumptions!$E$87*(1+Assumptions!$E$85)+Assumptions!$E$88+Assumptions!$E$89/Assumptions!$E$10) -> 106.09625 | E17: =Assumptions!$F$91*(Assumptions!$F$86*Assumptions!$F$83*(1+Assumptions!$F$85)+Assumptions!$F$11*Assumptions!$F$87*(1+Assumptions!$F$85)+Assumptions!$F$88+Assumptions!$F$89/Assumptions!$F$10) -> 106.09625 | F17: =Assumptions!$G$91*(Assumptions!$G$86*Assumptions!$G$83*(1+Assumptions!$G$85)+Assumptions!$G$11*Assumptions!$G$87*(1+Assumptions!$G$85)+Assumptions!$G$88+Assumptions!$G$89/Assumptions!$G$10) -> 95.078842
A18: CAC per activated merchant | B18: =B17/Assumptions!$C$11 -> 176.82708 | C18: =C17/Assumptions!$D$11 -> 262.7345 | D18: =D17/Assumptions!$E$11 -> 176.82708 | E18: =E17/Assumptions!$F$11 -> 176.82708 | F18: =F17/Assumptions!$G$11 -> 135.82692
A19: CAC per paying merchant | B19: =B17/(Assumptions!$C$11*B9)+Assumptions!$C$90*Assumptions!$C$91 -> 553.06425 | C19: =C17/(Assumptions!$D$11*C9)+Assumptions!$D$90*Assumptions!$D$91 -> 1170.3799 | D19: =D17/(Assumptions!$E$11*D9)+Assumptions!$E$90*Assumptions!$E$91 -> 553.06425 | E19: =E17/(Assumptions!$F$11*E9)+Assumptions!$F$90*Assumptions!$F$91 -> 553.06425 | F19: =F17/(Assumptions!$G$11*F9)+Assumptions!$G$90*Assumptions!$G$91 -> 370.30061
A20: Average paid life (months) | B20: =1/Assumptions!$C$41 -> 33.333333 | C20: =1/Assumptions!$D$41 -> 22.222222 | D20: =1/Assumptions!$E$41 -> 33.333333 | E20: =1/Assumptions!$F$41 -> 33.333333 | F20: =1/Assumptions!$G$41 -> 44.444444
A21: LTV per paying merchant (undiscounted contribution) | B21: =B16*B20 -> 1463.416 | C21: =C16*C20 -> 913.92725 | D21: =D16*D20 -> 1463.416 | E21: =E16*E20 -> 1463.416 | F21: =F16*F20 -> 2042.3181
A22: LTV / CAC | B22: =B21/B19 -> 2.6460144 | C22: =C21/C19 -> 0.78088083 | D22: =D21/D19 -> 2.6460144 | E22: =E21/E19 -> 2.6460144 | F22: =F21/F19 -> 5.5152978
A23: CAC payback (months) | B23: =B19/B16 -> 12.597563 | C23: =C19/C16 -> 28.457892 | D23: =D19/D16 -> 12.597563 | E23: =E19/E16 -> 12.597563 | F23: =F19/F16 -> 8.0583943
A24: Free-tier carry cost per paying merchant (24 months) | B24: =(1-B9)/B9*B8*24 -> 204.65242 | C24: =(1-C9)/C9*C8*24 -> 321.91639 | D24: =(1-D9)/D9*D8*24 -> 204.65242 | E24: =(1-E9)/E9*E8*24 -> 204.65242 | F24: =(1-F9)/F9*F8*24 -> 167.37098
A25: LTV / (CAC + free carry), fully loaded | B25: =B21/(B19+B24) -> 1.9313498 | C25: =C21/(C19+C24) -> 0.61243015 | D25: =D21/(D19+D24) -> 1.9313498 | E25: =E21/(E19+E24) -> 1.9313498 | F25: =F21/(F19+F24) -> 3.7984491
A26: Merchant all-in cost of an in-app payment (Stripe + 0.75%) | B26: =Assumptions!$C$49+Assumptions!$C$50/Assumptions!$C$48+Assumptions!$C$44 -> 0.045071429 | C26: =Assumptions!$D$49+Assumptions!$D$50/Assumptions!$D$48+Assumptions!$D$44 -> 0.045071429 | D26: =Assumptions!$E$49+Assumptions!$E$50/Assumptions!$E$48+Assumptions!$E$44 -> 0.045071429 | E26: =Assumptions!$F$49+Assumptions!$F$50/Assumptions!$F$48+Assumptions!$F$44 -> 0.045071429 | F26: =Assumptions!$G$49+Assumptions!$G$50/Assumptions!$G$48+Assumptions!$G$44 -> 0.045071429

Sheet Monthly
A1: Local Loyalty — monthly model: Base scenario (CAD)
A2: Every cell is a formula driven by the Assumptions sheet (column C). Months 1-36 = projection; grey months 37-60 = extension used only to locate break-even.
B4: Model month | C4: 0 | D4: 1 | E4: 2 | F4: 3 | G4: 4 | H4: 5 | I4: 6 | J4: 7 | K4: 8 | L4: 9 | M4: 10 | N4: 11 | O4: 12 | P4: 13 | Q4: 14 | R4: 15 | S4: 16 | T4: 17 | U4: 18 | V4: 19 | W4: 20 | X4: 21 | Y4: 22 | Z4: 23 | AA4: 24 | AB4: 25 | AC4: 26 | AD4: 27 | AE4: 28 | AF4: 29 | AG4: 30 | AH4: 31 | AI4: 32 | AJ4: 33 | AK4: 34 | AL4: 35 | AM4: 36 | AN4: 37 | AO4: 38 | AP4: 39 | AQ4: 40 | AR4: 41 | AS4: 42 | AT4: 43 | AU4: 44 | AV4: 45 | AW4: 46 | AX4: 47 | AY4: 48 | AZ4: 49 | BA4: 50 | BB4: 51 | BC4: 52 | BD4: 53 | BE4: 54 | BF4: 55 | BG4: 56 | BH4: 57 | BI4: 58 | BJ4: 59 | BK4: 60
B5: Calendar month | C5: start | D5: 2026-11 | E5: 2026-12 | F5: 2027-01 | G5: 2027-02 | H5: 2027-03 | I5: 2027-04 | J5: 2027-05 | K5: 2027-06 | L5: 2027-07 | M5: 2027-08 | N5: 2027-09 | O5: 2027-10 | P5: 2027-11 | Q5: 2027-12 | R5: 2028-01 | S5: 2028-02 | T5: 2028-03 | U5: 2028-04 | V5: 2028-05 | W5: 2028-06 | X5: 2028-07 | Y5: 2028-08 | Z5: 2028-09 | AA5: 2028-10 | AB5: 2028-11 | AC5: 2028-12 | AD5: 2029-01 | AE5: 2029-02 | AF5: 2029-03 | AG5: 2029-04 | AH5: 2029-05 | AI5: 2029-06 | AJ5: 2029-07 | AK5: 2029-08 | AL5: 2029-09 | AM5: 2029-10 | AN5: 2029-11 | AO5: 2029-12 | AP5: 2030-01 | AQ5: 2030-02 | AR5: 2030-03 | AS5: 2030-04 | AT5: 2030-05 | AU5: 2030-06 | AV5: 2030-07 | AW5: 2030-08 | AX5: 2030-09 | AY5: 2030-10 | AZ5: 2030-11 | BA5: 2030-12 | BB5: 2031-01 | BC5: 2031-02 | BD5: 2031-03 | BE5: 2031-04 | BF5: 2031-05 | BG5: 2031-06 | BH5: 2031-07 | BI5: 2031-08 | BJ5: 2031-09 | BK5: 2031-10
B6: Strips & merchants
A7: month | B7: Model month | C7: 0 | D7: 1 | E7: 2 | F7: 3 | G7: 4 | H7: 5 | I7: 6 | J7: 7 | K7: 8 | L7: 9 | M7: 10 | N7: 11 | O7: 12 | P7: 13 | Q7: 14 | R7: 15 | S7: 16 | T7: 17 | U7: 18 | V7: 19 | W7: 20 | X7: 21 | Y7: 22 | Z7: 23 | AA7: 24 | AB7: 25 | AC7: 26 | AD7: 27 | AE7: 28 | AF7: 29 | AG7: 30 | AH7: 31 | AI7: 32 | AJ7: 33 | AK7: 34 | AL7: 35 | AM7: 36 | AN7: 37 | AO7: 38 | AP7: 39 | AQ7: 40 | AR7: 41 | AS7: 42 | AT7: 43 | AU7: 44 | AV7: 45 | AW7: 46 | AX7: 47 | AY7: 48 | AZ7: 49 | BA7: 50 | BB7: 51 | BC7: 52 | BD7: 53 | BE7: 54 | BF7: 55 | BG7: 56 | BH7: 57 | BI7: 58 | BJ7: 59 | BK7: 60
A8: strips_launched | B8: Strips launched | C8: 0 | D8: =Assumptions!C$139 -> 0 | E8: =Assumptions!D$139 -> 0 | F8: =Assumptions!E$139 -> 0 | G8: =Assumptions!F$139 -> 0 | H8: =Assumptions!G$139 -> 1 | I8: =Assumptions!H$139 -> 0 | J8: =Assumptions!I$139 -> 0 | K8: =Assumptions!J$139 -> 1 | ... BK8: =Assumptions!BJ$139 -> 1
A9: strips_cum | B9: Strips live (cumulative) | C9: 0 | D9: =C9+D8 -> 0 | E9: =D9+E8 -> 0 | F9: =E9+F8 -> 0 | G9: =F9+G8 -> 0 | H9: =G9+H8 -> 1 | I9: =H9+I8 -> 1 | J9: =I9+J8 -> 1 | K9: =J9+K8 -> 2 | ... BK9: =BJ9+BK8 -> 61
A10: strips_mature | B10: Mature strips (launched >= maturity months ago) | C10: 0 | D10: =IF(D7>Assumptions!$C$79,INDEX($D$9:$BK$9,D7-Assumptions!$C$79),0) -> 0 | E10: =IF(E7>Assumptions!$C$79,INDEX($D$9:$BK$9,E7-Assumptions!$C$79),0) -> 0 | F10: =IF(F7>Assumptions!$C$79,INDEX($D$9:$BK$9,F7-Assumptions!$C$79),0) -> 0 | G10: =IF(G7>Assumptions!$C$79,INDEX($D$9:$BK$9,G7-Assumptions!$C$79),0) -> 0 | H10: =IF(H7>Assumptions!$C$79,INDEX($D$9:$BK$9,H7-Assumptions!$C$79),0) -> 0 | I10: =IF(I7>Assumptions!$C$79,INDEX($D$9:$BK$9,I7-Assumptions!$C$79),0) -> 0 | J10: =IF(J7>Assumptions!$C$79,INDEX($D$9:$BK$9,J7-Assumptions!$C$79),0) -> 0 | K10: =IF(K7>Assumptions!$C$79,INDEX($D$9:$BK$9,K7-Assumptions!$C$79),0) -> 0 | ... BK10: =IF(BK7>Assumptions!$C$79,INDEX($D$9:$BK$9,BK7-Assumptions!$C$79),0) -> 53
A11: signups | B11: New merchant sign-ups | C11: 0 | D11: =Assumptions!$C$10*(D8*Assumptions!$C$111) -> 0 | E11: =Assumptions!$C$10*(E8*Assumptions!$C$111+D8*Assumptions!$C$112) -> 0 | F11: =Assumptions!$C$10*(F8*Assumptions!$C$111+E8*Assumptions!$C$112+D8*Assumptions!$C$113) -> 0 | G11: =Assumptions!$C$10*(G8*Assumptions!$C$111+F8*Assumptions!$C$112+E8*Assumptions!$C$113+D8*Assumptions!$C$114) -> 0 | H11: =Assumptions!$C$10*(H8*Assumptions!$C$111+G8*Assumptions!$C$112+F8*Assumptions!$C$113+E8*Assumptions!$C$114+D8*Assumptions!$C$115) -> 8 | I11: =Assumptions!$C$10*(I8*Assumptions!$C$111+H8*Assumptions!$C$112+G8*Assumptions!$C$113+F8*Assumptions!$C$114+E8*Assumptions!$C$115+D8*Assumptions!$C$116) -> 7.04 | J11: =Assumptions!$C$10*(J8*Assumptions!$C$111+I8*Assumptions!$C$112+H8*Assumptions!$C$113+G8*Assumptions!$C$114+F8*Assumptions!$C$115+E8*Assumptions!$C$116+D8*Assumptions!$C$117) -> 4.8 | K11: =Assumptions!$C$10*(K8*Assumptions!$C$111+J8*Assumptions!$C$112+I8*Assumptions!$C$113+H8*Assumptions!$C$114+G8*Assumptions!$C$115+F8*Assumptions!$C$116+E8*Assumptions!$C$117+D8*Assumptions!$C$118) -> 11.2 | L11: =Assumptions!$C$10*(L8*Assumptions!$C$111+K8*Assumptions!$C$112+J8*Assumptions!$C$113+I8*Assumptions!$C$114+H8*Assumptions!$C$115+G8*Assumptions!$C$116+F8*Assumptions!$C$117+E8*Assumptions!$C$118+D8*Assumptions!$C$119) -> 8.96 | M11: =Assumptions!$C$10*(M8*Assumptions!$C$111+L8*Assumptions!$C$112+K8*Assumptions!$C$113+J8*Assumptions!$C$114+I8*Assumptions!$C$115+H8*Assumptions!$C$116+G8*Assumptions!$C$117+F8*Assumptions!$C$118+E8*Assumptions!$C$119+D8*Assumptions!$C$120) -> 6.4 | N11: =Assumptions!$C$10*(N8*Assumptions!$C$111+M8*Assumptions!$C$112+L8*Assumptions!$C$113+K8*Assumptions!$C$114+J8*Assumptions!$C$115+I8*Assumptions!$C$116+H8*Assumptions!$C$117+G8*Assumptions!$C$118+F8*Assumptions!$C$119+E8*Assumptions!$C$120+D8*Assumptions!$C$121) -> 11.52 | O11: =Assumptions!$C$10*(O8*Assumptions!$C$111+N8*Assumptions!$C$112+M8*Assumptions!$C$113+L8*Assumptions!$C$114+K8*Assumptions!$C$115+J8*Assumptions!$C$116+I8*Assumptions!$C$117+H8*Assumptions!$C$118+G8*Assumptions!$C$119+F8*Assumptions!$C$120+E8*Assumptions!$C$121+D8*Assumptions!$C$122) -> 17.28 | P11: =Assumptions!$C$10*(P8*Assumptions!$C$111+O8*Assumptions!$C$112+N8*Assumptions!$C$113+M8*Assumptions!$C$114+L8*Assumptions!$C$115+K8*Assumptions!$C$116+J8*Assumptions!$C$117+I8*Assumptions!$C$118+H8*Assumptions!$C$119+G8*Assumptions!$C$120+F8*Assumptions!$C$121+E8*Assumptions!$C$122+D8*Assumptions!$C$123) -> 13.76 | Q11: =Assumptions!$C$10*(Q8*Assumptions!$C$111+P8*Assumptions!$C$112+O8*Assumptions!$C$113+N8*Assumptions!$C$114+M8*Assumptions!$C$115+L8*Assumptions!$C$116+K8*Assumptions!$C$117+J8*Assumptions!$C$118+I8*Assumptions!$C$119+H8*Assumptions!$C$120+G8*Assumptions!$C$121+F8*Assumptions!$C$122+E8*Assumptions!$C$123+D8*Assumptions!$C$124) -> 16.64 | R11: =Assumptions!$C$10*(R8*Assumptions!$C$111+Q8*Assumptions!$C$112+P8*Assumptions!$C$113+O8*Assumptions!$C$114+N8*Assumptions!$C$115+M8*Assumptions!$C$116+L8*Assumptions!$C$117+K8*Assumptions!$C$118+J8*Assumptions!$C$119+I8*Assumptions!$C$120+H8*Assumptions!$C$121+G8*Assumptions!$C$122+F8*Assumptions!$C$123+E8*Assumptions!$C$124+D8*Assumptions!$C$125) -> 20.8 | S11: =Assumptions!$C$10*(S8*Assumptions!$C$111+R8*Assumptions!$C$112+Q8*Assumptions!$C$113+P8*Assumptions!$C$114+O8*Assumptions!$C$115+N8*Assumptions!$C$116+M8*Assumptions!$C$117+L8*Assumptions!$C$118+K8*Assumptions!$C$119+J8*Assumptions!$C$120+I8*Assumptions!$C$121+H8*Assumptions!$C$122+G8*Assumptions!$C$123+F8*Assumptions!$C$124+E8*Assumptions!$C$125+D8*Assumptions!$C$126) -> 16 | T11: =Assumptions!$C$10*(T8*Assumptions!$C$111+S8*Assumptions!$C$112+R8*Assumptions!$C$113+Q8*Assumptions!$C$114+P8*Assumptions!$C$115+O8*Assumptions!$C$116+N8*Assumptions!$C$117+M8*Assumptions!$C$118+L8*Assumptions!$C$119+K8*Assumptions!$C$120+J8*Assumptions!$C$121+I8*Assumptions!$C$122+H8*Assumptions!$C$123+G8*Assumptions!$C$124+F8*Assumptions!$C$125+E8*Assumptions!$C$126+D8*Assumptions!$C$127) -> 18.56 | U11: =Assumptions!$C$10*(U8*Assumptions!$C$111+T8*Assumptions!$C$112+S8*Assumptions!$C$113+R8*Assumptions!$C$114+Q8*Assumptions!$C$115+P8*Assumptions!$C$116+O8*Assumptions!$C$117+N8*Assumptions!$C$118+M8*Assumptions!$C$119+L8*Assumptions!$C$120+K8*Assumptions!$C$121+J8*Assumptions!$C$122+I8*Assumptions!$C$123+H8*Assumptions!$C$124+G8*Assumptions!$C$125+F8*Assumptions!$C$126+E8*Assumptions!$C$127+D8*Assumptions!$C$128) -> 21.44 | V11: =Assumptions!$C$10*(V8*Assumptions!$C$111+U8*Assumptions!$C$112+T8*Assumptions!$C$113+S8*Assumptions!$C$114+R8*Assumptions!$C$115+Q8*Assumptions!$C$116+P8*Assumptions!$C$117+O8*Assumptions!$C$118+N8*Assumptions!$C$119+M8*Assumptions!$C$120+L8*Assumptions!$C$121+K8*Assumptions!$C$122+J8*Assumptions!$C$123+I8*Assumptions!$C$124+H8*Assumptions!$C$125+G8*Assumptions!$C$126+F8*Assumptions!$C$127+E8*Assumptions!$C$128+D8*Assumptions!$C$129) -> 24.64 | W11: =Assumptions!$C$10*(W8*Assumptions!$C$111+V8*Assumptions!$C$112+U8*Assumptions!$C$113+T8*Assumptions!$C$114+S8*Assumptions!$C$115+R8*Assumptions!$C$116+Q8*Assumptions!$C$117+P8*Assumptions!$C$118+O8*Assumptions!$C$119+N8*Assumptions!$C$120+M8*Assumptions!$C$121+L8*Assumptions!$C$122+K8*Assumptions!$C$123+J8*Assumptions!$C$124+I8*Assumptions!$C$125+H8*Assumptions!$C$126+G8*Assumptions!$C$127+F8*Assumptions!$C$128+E8*Assumptions!$C$129+D8*Assumptions!$C$130) -> 26.24 | X11: =Assumptions!$C$10*(X8*Assumptions!$C$111+W8*Assumptions!$C$112+V8*Assumptions!$C$113+U8*Assumptions!$C$114+T8*Assumptions!$C$115+S8*Assumptions!$C$116+R8*Assumptions!$C$117+Q8*Assumptions!$C$118+P8*Assumptions!$C$119+O8*Assumptions!$C$120+N8*Assumptions!$C$121+M8*Assumptions!$C$122+L8*Assumptions!$C$123+K8*Assumptions!$C$124+J8*Assumptions!$C$125+I8*Assumptions!$C$126+H8*Assumptions!$C$127+G8*Assumptions!$C$128+F8*Assumptions!$C$129+E8*Assumptions!$C$130+D8*Assumptions!$C$131) -> 26.88 | Y11: =Assumptions!$C$10*(Y8*Assumptions!$C$111+X8*Assumptions!$C$112+W8*Assumptions!$C$113+V8*Assumptions!$C$114+U8*Assumptions!$C$115+T8*Assumptions!$C$116+S8*Assumptions!$C$117+R8*Assumptions!$C$118+Q8*Assumptions!$C$119+P8*Assumptions!$C$120+O8*Assumptions!$C$121+N8*Assumptions!$C$122+M8*Assumptions!$C$123+L8*Assumptions!$C$124+K8*Assumptions!$C$125+J8*Assumptions!$C$126+I8*Assumptions!$C$127+H8*Assumptions!$C$128+G8*Assumptions!$C$129+F8*Assumptions!$C$130+E8*Assumptions!$C$131+D8*Assumptions!$C$132) -> 28.48 | Z11: =Assumptions!$C$10*(Z8*Assumptions!$C$111+Y8*Assumptions!$C$112+X8*Assumptions!$C$113+W8*Assumptions!$C$114+V8*Assumptions!$C$115+U8*Assumptions!$C$116+T8*Assumptions!$C$117+S8*Assumptions!$C$118+R8*Assumptions!$C$119+Q8*Assumptions!$C$120+P8*Assumptions!$C$121+O8*Assumptions!$C$122+N8*Assumptions!$C$123+M8*Assumptions!$C$124+L8*Assumptions!$C$125+K8*Assumptions!$C$126+J8*Assumptions!$C$127+I8*Assumptions!$C$128+H8*Assumptions!$C$129+G8*Assumptions!$C$130+F8*Assumptions!$C$131+E8*Assumptions!$C$132+D8*Assumptions!$C$133) -> 28.8 | AA11: =Assumptions!$C$10*(AA8*Assumptions!$C$111+Z8*Assumptions!$C$112+Y8*Assumptions!$C$113+X8*Assumptions!$C$114+W8*Assumptions!$C$115+V8*Assumptions!$C$116+U8*Assumptions!$C$117+T8*Assumptions!$C$118+S8*Assumptions!$C$119+R8*Assumptions!$C$120+Q8*Assumptions!$C$121+P8*Assumptions!$C$122+O8*Assumptions!$C$123+N8*Assumptions!$C$124+M8*Assumptions!$C$125+L8*Assumptions!$C$126+K8*Assumptions!$C$127+J8*Assumptions!$C$128+I8*Assumptions!$C$129+H8*Assumptions!$C$130+G8*Assumptions!$C$131+F8*Assumptions!$C$132+E8*Assumptions!$C$133) -> 29.12 | AB11: =Assumptions!$C$10*(AB8*Assumptions!$C$111+AA8*Assumptions!$C$112+Z8*Assumptions!$C$113+Y8*Assumptions!$C$114+X8*Assumptions!$C$115+W8*Assumptions!$C$116+V8*Assumptions!$C$117+U8*Assumptions!$C$118+T8*Assumptions!$C$119+S8*Assumptions!$C$120+R8*Assumptions!$C$121+Q8*Assumptions!$C$122+P8*Assumptions!$C$123+O8*Assumptions!$C$124+N8*Assumptions!$C$125+M8*Assumptions!$C$126+L8*Assumptions!$C$127+K8*Assumptions!$C$128+J8*Assumptions!$C$129+I8*Assumptions!$C$130+H8*Assumptions!$C$131+G8*Assumptions!$C$132+F8*Assumptions!$C$133) -> 29.44 | AC11: =Assumptions!$C$10*(AC8*Assumptions!$C$111+AB8*Assumptions!$C$112+AA8*Assumptions!$C$113+Z8*Assumptions!$C$114+Y8*Assumptions!$C$115+X8*Assumptions!$C$116+W8*Assumptions!$C$117+V8*Assumptions!$C$118+U8*Assumptions!$C$119+T8*Assumptions!$C$120+S8*Assumptions!$C$121+R8*Assumptions!$C$122+Q8*Assumptions!$C$123+P8*Assumptions!$C$124+O8*Assumptions!$C$125+N8*Assumptions!$C$126+M8*Assumptions!$C$127+L8*Assumptions!$C$128+K8*Assumptions!$C$129+J8*Assumptions!$C$130+I8*Assumptions!$C$131+H8*Assumptions!$C$132+G8*Assumptions!$C$133) -> 29.76 | AD11: =Assumptions!$C$10*(AD8*Assumptions!$C$111+AC8*Assumptions!$C$112+AB8*Assumptions!$C$113+AA8*Assumptions!$C$114+Z8*Assumptions!$C$115+Y8*Assumptions!$C$116+X8*Assumptions!$C$117+W8*Assumptions!$C$118+V8*Assumptions!$C$119+U8*Assumptions!$C$120+T8*Assumptions!$C$121+S8*Assumptions!$C$122+R8*Assumptions!$C$123+Q8*Assumptions!$C$124+P8*Assumptions!$C$125+O8*Assumptions!$C$126+N8*Assumptions!$C$127+M8*Assumptions!$C$128+L8*Assumptions!$C$129+K8*Assumptions!$C$130+J8*Assumptions!$C$131+I8*Assumptions!$C$132+H8*Assumptions!$C$133) -> 30.08 | AE11: =Assumptions!$C$10*(AE8*Assumptions!$C$111+AD8*Assumptions!$C$112+AC8*Assumptions!$C$113+AB8*Assumptions!$C$114+AA8*Assumptions!$C$115+Z8*Assumptions!$C$116+Y8*Assumptions!$C$117+X8*Assumptions!$C$118+W8*Assumptions!$C$119+V8*Assumptions!$C$120+U8*Assumptions!$C$121+T8*Assumptions!$C$122+S8*Assumptions!$C$123+R8*Assumptions!$C$124+Q8*Assumptions!$C$125+P8*Assumptions!$C$126+O8*Assumptions!$C$127+N8*Assumptions!$C$128+M8*Assumptions!$C$129+L8*Assumptions!$C$130+K8*Assumptions!$C$131+J8*Assumptions!$C$132+I8*Assumptions!$C$133) -> 30.08 | AF11: =Assumptions!$C$10*(AF8*Assumptions!$C$111+AE8*Assumptions!$C$112+AD8*Assumptions!$C$113+AC8*Assumptions!$C$114+AB8*Assumptions!$C$115+AA8*Assumptions!$C$116+Z8*Assumptions!$C$117+Y8*Assumptions!$C$118+X8*Assumptions!$C$119+W8*Assumptions!$C$120+V8*Assumptions!$C$121+U8*Assumptions!$C$122+T8*Assumptions!$C$123+S8*Assumptions!$C$124+R8*Assumptions!$C$125+Q8*Assumptions!$C$126+P8*Assumptions!$C$127+O8*Assumptions!$C$128+N8*Assumptions!$C$129+M8*Assumptions!$C$130+L8*Assumptions!$C$131+K8*Assumptions!$C$132+J8*Assumptions!$C$133) -> 38.4 | AG11: =Assumptions!$C$10*(AG8*Assumptions!$C$111+AF8*Assumptions!$C$112+AE8*Assumptions!$C$113+AD8*Assumptions!$C$114+AC8*Assumptions!$C$115+AB8*Assumptions!$C$116+AA8*Assumptions!$C$117+Z8*Assumptions!$C$118+Y8*Assumptions!$C$119+X8*Assumptions!$C$120+W8*Assumptions!$C$121+V8*Assumptions!$C$122+U8*Assumptions!$C$123+T8*Assumptions!$C$124+S8*Assumptions!$C$125+R8*Assumptions!$C$126+Q8*Assumptions!$C$127+P8*Assumptions!$C$128+O8*Assumptions!$C$129+N8*Assumptions!$C$130+M8*Assumptions!$C$131+L8*Assumptions!$C$132+K8*Assumptions!$C$133) -> 37.76 | ... BK11: =Assumptions!$C$10*(BK8*Assumptions!$C$111+BJ8*Assumptions!$C$112+BI8*Assumptions!$C$113+BH8*Assumptions!$C$114+BG8*Assumptions!$C$115+BF8*Assumptions!$C$116+BE8*Assumptions!$C$117+BD8*Assumptions!$C$118+BC8*Assumptions!$C$119+BB8*Assumptions!$C$120+BA8*Assumptions!$C$121+AZ8*Assumptions!$C$122+AY8*Assumptions!$C$123+AX8*Assumptions!$C$124+AW8*Assumptions!$C$125+AV8*Assumptions!$C$126+AU8*Assumptions!$C$127+AT8*Assumptions!$C$128+AS8*Assumptions!$C$129+AR8*Assumptions!$C$130+AQ8*Assumptions!$C$131+AP8*Assumptions!$C$132+AO8*Assumptions!$C$133) -> 42.88
A12: network_merchants | B12: Network merchants (signed, net of churn) | C12: 0 | D12: =C12*(1-Assumptions!$C$12)+D11 -> 0 | E12: =D12*(1-Assumptions!$C$12)+E11 -> 0 | F12: =E12*(1-Assumptions!$C$12)+F11 -> 0 | G12: =F12*(1-Assumptions!$C$12)+G11 -> 0 | H12: =G12*(1-Assumptions!$C$12)+H11 -> 8 | I12: =H12*(1-Assumptions!$C$12)+I11 -> 14.92 | J12: =I12*(1-Assumptions!$C$12)+J11 -> 19.4962 | K12: =J12*(1-Assumptions!$C$12)+K11 -> 30.403757 | ... BK12: =BJ12*(1-Assumptions!$C$12)+BK11 -> 1320.3863
A13: active_merchants | B13: Active merchants (>= 25 active members) | C13: 0 | D13: =D12*Assumptions!$C$11 -> 0 | E13: =E12*Assumptions!$C$11 -> 0 | F13: =F12*Assumptions!$C$11 -> 0 | G13: =G12*Assumptions!$C$11 -> 0 | H13: =H12*Assumptions!$C$11 -> 4.8 | I13: =I12*Assumptions!$C$11 -> 8.952 | J13: =J12*Assumptions!$C$11 -> 11.69772 | K13: =K12*Assumptions!$C$11 -> 18.242254 | ... BK13: =BK12*Assumptions!$C$11 -> 792.23178
A14: activated_new | B14: Newly activated merchants | C14: 0 | D14: =D11*Assumptions!$C$11 -> 0 | E14: =E11*Assumptions!$C$11 -> 0 | F14: =F11*Assumptions!$C$11 -> 0 | G14: =G11*Assumptions!$C$11 -> 0 | H14: =H11*Assumptions!$C$11 -> 4.8 | I14: =I11*Assumptions!$C$11 -> 4.224 | J14: =J11*Assumptions!$C$11 -> 2.88 | K14: =K11*Assumptions!$C$11 -> 6.72 | ... BK14: =BK11*Assumptions!$C$11 -> 25.728
B15: Rollout gates (1 = unlocked; plans.ts unlockAtMerchants)
A16: plus_unlocked | B16: Plus features GA | C16: 0 | D16: =IF(OR(C16=1,AND(D13>=Assumptions!$C$18,D7>=Assumptions!$C$19)),1,0) -> 0 | E16: =IF(OR(D16=1,AND(E13>=Assumptions!$C$18,E7>=Assumptions!$C$19)),1,0) -> 0 | F16: =IF(OR(E16=1,AND(F13>=Assumptions!$C$18,F7>=Assumptions!$C$19)),1,0) -> 0 | G16: =IF(OR(F16=1,AND(G13>=Assumptions!$C$18,G7>=Assumptions!$C$19)),1,0) -> 0 | H16: =IF(OR(G16=1,AND(H13>=Assumptions!$C$18,H7>=Assumptions!$C$19)),1,0) -> 0 | I16: =IF(OR(H16=1,AND(I13>=Assumptions!$C$18,I7>=Assumptions!$C$19)),1,0) -> 0 | J16: =IF(OR(I16=1,AND(J13>=Assumptions!$C$18,J7>=Assumptions!$C$19)),1,0) -> 0 | K16: =IF(OR(J16=1,AND(K13>=Assumptions!$C$18,K7>=Assumptions!$C$19)),1,0) -> 0 | ... BK16: =IF(OR(BJ16=1,AND(BK13>=Assumptions!$C$18,BK7>=Assumptions!$C$19)),1,0) -> 1
A17: pro_unlocked | B17: Pro features GA | C17: 0 | D17: =IF(OR(C17=1,AND(D13>=Assumptions!$C$20,D7>=Assumptions!$C$21)),1,0) -> 0 | E17: =IF(OR(D17=1,AND(E13>=Assumptions!$C$20,E7>=Assumptions!$C$21)),1,0) -> 0 | F17: =IF(OR(E17=1,AND(F13>=Assumptions!$C$20,F7>=Assumptions!$C$21)),1,0) -> 0 | G17: =IF(OR(F17=1,AND(G13>=Assumptions!$C$20,G7>=Assumptions!$C$21)),1,0) -> 0 | H17: =IF(OR(G17=1,AND(H13>=Assumptions!$C$20,H7>=Assumptions!$C$21)),1,0) -> 0 | I17: =IF(OR(H17=1,AND(I13>=Assumptions!$C$20,I7>=Assumptions!$C$21)),1,0) -> 0 | J17: =IF(OR(I17=1,AND(J13>=Assumptions!$C$20,J7>=Assumptions!$C$21)),1,0) -> 0 | K17: =IF(OR(J17=1,AND(K13>=Assumptions!$C$20,K7>=Assumptions!$C$21)),1,0) -> 0 | ... BK17: =IF(OR(BJ17=1,AND(BK13>=Assumptions!$C$20,BK7>=Assumptions!$C$21)),1,0) -> 1
A18: bia_unlocked | B18: BIA campaigns available | C18: 0 | D18: =IF(OR(C18=1,D13>=Assumptions!$C$22),1,0) -> 0 | E18: =IF(OR(D18=1,E13>=Assumptions!$C$22),1,0) -> 0 | F18: =IF(OR(E18=1,F13>=Assumptions!$C$22),1,0) -> 0 | G18: =IF(OR(F18=1,G13>=Assumptions!$C$22),1,0) -> 0 | H18: =IF(OR(G18=1,H13>=Assumptions!$C$22),1,0) -> 0 | I18: =IF(OR(H18=1,I13>=Assumptions!$C$22),1,0) -> 0 | J18: =IF(OR(I18=1,J13>=Assumptions!$C$22),1,0) -> 0 | K18: =IF(OR(J18=1,K13>=Assumptions!$C$22),1,0) -> 0 | ... BK18: =IF(OR(BJ18=1,BK13>=Assumptions!$C$22),1,0) -> 1
A19: ads_unlocked | B19: Ads available | C19: 0 | D19: =IF(OR(C19=1,AND(D13>=Assumptions!$C$23,D7>=Assumptions!$C$24)),1,0) -> 0 | E19: =IF(OR(D19=1,AND(E13>=Assumptions!$C$23,E7>=Assumptions!$C$24)),1,0) -> 0 | F19: =IF(OR(E19=1,AND(F13>=Assumptions!$C$23,F7>=Assumptions!$C$24)),1,0) -> 0 | G19: =IF(OR(F19=1,AND(G13>=Assumptions!$C$23,G7>=Assumptions!$C$24)),1,0) -> 0 | H19: =IF(OR(G19=1,AND(H13>=Assumptions!$C$23,H7>=Assumptions!$C$24)),1,0) -> 0 | I19: =IF(OR(H19=1,AND(I13>=Assumptions!$C$23,I7>=Assumptions!$C$24)),1,0) -> 0 | J19: =IF(OR(I19=1,AND(J13>=Assumptions!$C$23,J7>=Assumptions!$C$24)),1,0) -> 0 | K19: =IF(OR(J19=1,AND(K13>=Assumptions!$C$23,K7>=Assumptions!$C$24)),1,0) -> 0 | ... BK19: =IF(OR(BJ19=1,AND(BK13>=Assumptions!$C$23,BK7>=Assumptions!$C$24)),1,0) -> 1
A20: ads_months | B20: Months since ads unlocked | C20: 0 | D20: =IF(D19=1,C20+1,0) -> 0 | E20: =IF(E19=1,D20+1,0) -> 0 | F20: =IF(F19=1,E20+1,0) -> 0 | G20: =IF(G19=1,F20+1,0) -> 0 | H20: =IF(H19=1,G20+1,0) -> 0 | I20: =IF(I19=1,H20+1,0) -> 0 | J20: =IF(J19=1,I20+1,0) -> 0 | K20: =IF(K19=1,J20+1,0) -> 0 | ... BK20: =IF(BK19=1,BJ20+1,0) -> 24
A21: ads_ramp | B21: Ad demand ramp | C21: 0 | D21: =MIN(1,D20/Assumptions!$C$77) -> 0 | E21: =MIN(1,E20/Assumptions!$C$77) -> 0 | F21: =MIN(1,F20/Assumptions!$C$77) -> 0 | G21: =MIN(1,G20/Assumptions!$C$77) -> 0 | H21: =MIN(1,H20/Assumptions!$C$77) -> 0 | I21: =MIN(1,I20/Assumptions!$C$77) -> 0 | J21: =MIN(1,J20/Assumptions!$C$77) -> 0 | K21: =MIN(1,K20/Assumptions!$C$77) -> 0 | ... BK21: =MIN(1,BK20/Assumptions!$C$77) -> 1
B22: Customers
A23: memberships | B23: Memberships (customer-shop pairs) | C23: 0 | D23: =C23+(D13*Assumptions!$C$13-C23)*Assumptions!$C$14 -> 0 | E23: =D23+(E13*Assumptions!$C$13-D23)*Assumptions!$C$14 -> 0 | F23: =E23+(F13*Assumptions!$C$13-E23)*Assumptions!$C$14 -> 0 | G23: =F23+(G13*Assumptions!$C$13-F23)*Assumptions!$C$14 -> 0 | H23: =G23+(H13*Assumptions!$C$13-G23)*Assumptions!$C$14 -> 126 | I23: =H23+(I13*Assumptions!$C$13-H23)*Assumptions!$C$14 -> 316.89 | J23: =I23+(J13*Assumptions!$C$13-I23)*Assumptions!$C$14 -> 513.04365 | K23: =J23+(K13*Assumptions!$C$13-J23)*Assumptions!$C$14 -> 812.33755 | ... BK23: =BJ23+(BK13*Assumptions!$C$13-BJ23)*Assumptions!$C$14 -> 57392.841
A24: active_customers | B24: Active customers (unique) | C24: 0 | D24: =D23/Assumptions!$C$15 -> 0 | E24: =E23/Assumptions!$C$15 -> 0 | F24: =F23/Assumptions!$C$15 -> 0 | G24: =G23/Assumptions!$C$15 -> 0 | H24: =H23/Assumptions!$C$15 -> 90 | I24: =I23/Assumptions!$C$15 -> 226.35 | J24: =J23/Assumptions!$C$15 -> 366.45975 | K24: =K23/Assumptions!$C$15 -> 580.2411 | ... BK24: =BK23/Assumptions!$C$15 -> 40994.887
A25: new_customers | B25: New / re-acquired customers | C25: 0 | D25: =MAX(0,D24-C24)+C24*Assumptions!$C$16 -> 0 | E25: =MAX(0,E24-D24)+D24*Assumptions!$C$16 -> 0 | F25: =MAX(0,F24-E24)+E24*Assumptions!$C$16 -> 0 | G25: =MAX(0,G24-F24)+F24*Assumptions!$C$16 -> 0 | H25: =MAX(0,H24-G24)+G24*Assumptions!$C$16 -> 90 | I25: =MAX(0,I24-H24)+H24*Assumptions!$C$16 -> 139.95 | J25: =MAX(0,J24-I24)+I24*Assumptions!$C$16 -> 149.16375 | K25: =MAX(0,K24-J24)+J24*Assumptions!$C$16 -> 228.43974 | ... BK25: =MAX(0,BK24-BJ24)+BJ24*Assumptions!$C$16 -> 2387.3187
B26: Paying merchants by vertical (repair/auto gated by Pro, others by Plus)
A27: paid_food_bev | B27: Paying — Cafes, restaurants, bakeries | C27: 0 | D27: =C27*(1-Assumptions!$C$41)+D16*((1-(1-Assumptions!$C$30)^(1/12))*Assumptions!$C$40)*MAX(0,D13*Assumptions!$C$25-C27) -> 0 | E27: =D27*(1-Assumptions!$C$41)+E16*((1-(1-Assumptions!$C$30)^(1/12))*Assumptions!$C$40)*MAX(0,E13*Assumptions!$C$25-D27) -> 0 | F27: =E27*(1-Assumptions!$C$41)+F16*((1-(1-Assumptions!$C$30)^(1/12))*Assumptions!$C$40)*MAX(0,F13*Assumptions!$C$25-E27) -> 0 | G27: =F27*(1-Assumptions!$C$41)+G16*((1-(1-Assumptions!$C$30)^(1/12))*Assumptions!$C$40)*MAX(0,G13*Assumptions!$C$25-F27) -> 0 | H27: =G27*(1-Assumptions!$C$41)+H16*((1-(1-Assumptions!$C$30)^(1/12))*Assumptions!$C$40)*MAX(0,H13*Assumptions!$C$25-G27) -> 0 | I27: =H27*(1-Assumptions!$C$41)+I16*((1-(1-Assumptions!$C$30)^(1/12))*Assumptions!$C$40)*MAX(0,I13*Assumptions!$C$25-H27) -> 0 | J27: =I27*(1-Assumptions!$C$41)+J16*((1-(1-Assumptions!$C$30)^(1/12))*Assumptions!$C$40)*MAX(0,J13*Assumptions!$C$25-I27) -> 0 | K27: =J27*(1-Assumptions!$C$41)+K16*((1-(1-Assumptions!$C$30)^(1/12))*Assumptions!$C$40)*MAX(0,K13*Assumptions!$C$25-J27) -> 0 | ... BK27: =BJ27*(1-Assumptions!$C$41)+BK16*((1-(1-Assumptions!$C$30)^(1/12))*Assumptions!$C$40)*MAX(0,BK13*Assumptions!$C$25-BJ27) -> 66.433033
A28: paid_retail | B28: Paying — Independent retail | C28: 0 | D28: =C28*(1-Assumptions!$C$41)+D16*((1-(1-Assumptions!$C$31)^(1/12))*Assumptions!$C$40)*MAX(0,D13*Assumptions!$C$26-C28) -> 0 | E28: =D28*(1-Assumptions!$C$41)+E16*((1-(1-Assumptions!$C$31)^(1/12))*Assumptions!$C$40)*MAX(0,E13*Assumptions!$C$26-D28) -> 0 | F28: =E28*(1-Assumptions!$C$41)+F16*((1-(1-Assumptions!$C$31)^(1/12))*Assumptions!$C$40)*MAX(0,F13*Assumptions!$C$26-E28) -> 0 | G28: =F28*(1-Assumptions!$C$41)+G16*((1-(1-Assumptions!$C$31)^(1/12))*Assumptions!$C$40)*MAX(0,G13*Assumptions!$C$26-F28) -> 0 | H28: =G28*(1-Assumptions!$C$41)+H16*((1-(1-Assumptions!$C$31)^(1/12))*Assumptions!$C$40)*MAX(0,H13*Assumptions!$C$26-G28) -> 0 | I28: =H28*(1-Assumptions!$C$41)+I16*((1-(1-Assumptions!$C$31)^(1/12))*Assumptions!$C$40)*MAX(0,I13*Assumptions!$C$26-H28) -> 0 | J28: =I28*(1-Assumptions!$C$41)+J16*((1-(1-Assumptions!$C$31)^(1/12))*Assumptions!$C$40)*MAX(0,J13*Assumptions!$C$26-I28) -> 0 | K28: =J28*(1-Assumptions!$C$41)+K16*((1-(1-Assumptions!$C$31)^(1/12))*Assumptions!$C$40)*MAX(0,K13*Assumptions!$C$26-J28) -> 0 | ... BK28: =BJ28*(1-Assumptions!$C$41)+BK16*((1-(1-Assumptions!$C$31)^(1/12))*Assumptions!$C$40)*MAX(0,BK13*Assumptions!$C$26-BJ28) -> 29.695505
A29: paid_repair_auto | B29: Paying — Repair, auto, alterations, print | C29: 0 | D29: =C29*(1-Assumptions!$C$41)+D17*((1-(1-Assumptions!$C$32)^(1/12))*Assumptions!$C$40)*MAX(0,D13*Assumptions!$C$27-C29) -> 0 | E29: =D29*(1-Assumptions!$C$41)+E17*((1-(1-Assumptions!$C$32)^(1/12))*Assumptions!$C$40)*MAX(0,E13*Assumptions!$C$27-D29) -> 0 | F29: =E29*(1-Assumptions!$C$41)+F17*((1-(1-Assumptions!$C$32)^(1/12))*Assumptions!$C$40)*MAX(0,F13*Assumptions!$C$27-E29) -> 0 | G29: =F29*(1-Assumptions!$C$41)+G17*((1-(1-Assumptions!$C$32)^(1/12))*Assumptions!$C$40)*MAX(0,G13*Assumptions!$C$27-F29) -> 0 | H29: =G29*(1-Assumptions!$C$41)+H17*((1-(1-Assumptions!$C$32)^(1/12))*Assumptions!$C$40)*MAX(0,H13*Assumptions!$C$27-G29) -> 0 | I29: =H29*(1-Assumptions!$C$41)+I17*((1-(1-Assumptions!$C$32)^(1/12))*Assumptions!$C$40)*MAX(0,I13*Assumptions!$C$27-H29) -> 0 | J29: =I29*(1-Assumptions!$C$41)+J17*((1-(1-Assumptions!$C$32)^(1/12))*Assumptions!$C$40)*MAX(0,J13*Assumptions!$C$27-I29) -> 0 | K29: =J29*(1-Assumptions!$C$41)+K17*((1-(1-Assumptions!$C$32)^(1/12))*Assumptions!$C$40)*MAX(0,K13*Assumptions!$C$27-J29) -> 0 | ... BK29: =BJ29*(1-Assumptions!$C$41)+BK17*((1-(1-Assumptions!$C$32)^(1/12))*Assumptions!$C$40)*MAX(0,BK13*Assumptions!$C$27-BJ29) -> 68.504829
A30: paid_personal_services | B30: Paying — Salons, barbers, fitness, pets | C30: 0 | D30: =C30*(1-Assumptions!$C$41)+D16*((1-(1-Assumptions!$C$33)^(1/12))*Assumptions!$C$40)*MAX(0,D13*Assumptions!$C$28-C30) -> 0 | E30: =D30*(1-Assumptions!$C$41)+E16*((1-(1-Assumptions!$C$33)^(1/12))*Assumptions!$C$40)*MAX(0,E13*Assumptions!$C$28-D30) -> 0 | F30: =E30*(1-Assumptions!$C$41)+F16*((1-(1-Assumptions!$C$33)^(1/12))*Assumptions!$C$40)*MAX(0,F13*Assumptions!$C$28-E30) -> 0 | G30: =F30*(1-Assumptions!$C$41)+G16*((1-(1-Assumptions!$C$33)^(1/12))*Assumptions!$C$40)*MAX(0,G13*Assumptions!$C$28-F30) -> 0 | H30: =G30*(1-Assumptions!$C$41)+H16*((1-(1-Assumptions!$C$33)^(1/12))*Assumptions!$C$40)*MAX(0,H13*Assumptions!$C$28-G30) -> 0 | I30: =H30*(1-Assumptions!$C$41)+I16*((1-(1-Assumptions!$C$33)^(1/12))*Assumptions!$C$40)*MAX(0,I13*Assumptions!$C$28-H30) -> 0 | J30: =I30*(1-Assumptions!$C$41)+J16*((1-(1-Assumptions!$C$33)^(1/12))*Assumptions!$C$40)*MAX(0,J13*Assumptions!$C$28-I30) -> 0 | K30: =J30*(1-Assumptions!$C$41)+K16*((1-(1-Assumptions!$C$33)^(1/12))*Assumptions!$C$40)*MAX(0,K13*Assumptions!$C$28-J30) -> 0 | ... BK30: =BJ30*(1-Assumptions!$C$41)+BK16*((1-(1-Assumptions!$C$33)^(1/12))*Assumptions!$C$40)*MAX(0,BK13*Assumptions!$C$28-BJ30) -> 17.537441
A31: paid_pharmacy | B31: Paying — Independent pharmacies (front store only) | C31: 0 | D31: =C31*(1-Assumptions!$C$41)+D16*((1-(1-Assumptions!$C$34)^(1/12))*Assumptions!$C$40)*MAX(0,D13*Assumptions!$C$29-C31) -> 0 | E31: =D31*(1-Assumptions!$C$41)+E16*((1-(1-Assumptions!$C$34)^(1/12))*Assumptions!$C$40)*MAX(0,E13*Assumptions!$C$29-D31) -> 0 | F31: =E31*(1-Assumptions!$C$41)+F16*((1-(1-Assumptions!$C$34)^(1/12))*Assumptions!$C$40)*MAX(0,F13*Assumptions!$C$29-E31) -> 0 | G31: =F31*(1-Assumptions!$C$41)+G16*((1-(1-Assumptions!$C$34)^(1/12))*Assumptions!$C$40)*MAX(0,G13*Assumptions!$C$29-F31) -> 0 | H31: =G31*(1-Assumptions!$C$41)+H16*((1-(1-Assumptions!$C$34)^(1/12))*Assumptions!$C$40)*MAX(0,H13*Assumptions!$C$29-G31) -> 0 | I31: =H31*(1-Assumptions!$C$41)+I16*((1-(1-Assumptions!$C$34)^(1/12))*Assumptions!$C$40)*MAX(0,I13*Assumptions!$C$29-H31) -> 0 | J31: =I31*(1-Assumptions!$C$41)+J16*((1-(1-Assumptions!$C$34)^(1/12))*Assumptions!$C$40)*MAX(0,J13*Assumptions!$C$29-I31) -> 0 | K31: =J31*(1-Assumptions!$C$41)+K16*((1-(1-Assumptions!$C$34)^(1/12))*Assumptions!$C$40)*MAX(0,K13*Assumptions!$C$29-J31) -> 0 | ... BK31: =BJ31*(1-Assumptions!$C$41)+BK16*((1-(1-Assumptions!$C$34)^(1/12))*Assumptions!$C$40)*MAX(0,BK13*Assumptions!$C$29-BJ31) -> 4.109074
A32: paid_total | B32: Paying merchants (total) | C32: 0 | D32: =D27+D28+D29+D30+D31 -> 0 | E32: =E27+E28+E29+E30+E31 -> 0 | F32: =F27+F28+F29+F30+F31 -> 0 | G32: =G27+G28+G29+G30+G31 -> 0 | H32: =H27+H28+H29+H30+H31 -> 0 | I32: =I27+I28+I29+I30+I31 -> 0 | J32: =J27+J28+J29+J30+J31 -> 0 | K32: =K27+K28+K29+K30+K31 -> 0 | ... BK32: =BK27+BK28+BK29+BK30+BK31 -> 186.27988
A33: plus_merchants | B33: Plus merchants | D33: =D27*(1-Assumptions!$C$35)+D28*(1-Assumptions!$C$36)+D29*(1-Assumptions!$C$37)+D30*(1-Assumptions!$C$38)+D31*(1-Assumptions!$C$39) -> 0 | E33: =E27*(1-Assumptions!$C$35)+E28*(1-Assumptions!$C$36)+E29*(1-Assumptions!$C$37)+E30*(1-Assumptions!$C$38)+E31*(1-Assumptions!$C$39) -> 0 | F33: =F27*(1-Assumptions!$C$35)+F28*(1-Assumptions!$C$36)+F29*(1-Assumptions!$C$37)+F30*(1-Assumptions!$C$38)+F31*(1-Assumptions!$C$39) -> 0 | G33: =G27*(1-Assumptions!$C$35)+G28*(1-Assumptions!$C$36)+G29*(1-Assumptions!$C$37)+G30*(1-Assumptions!$C$38)+G31*(1-Assumptions!$C$39) -> 0 | H33: =H27*(1-Assumptions!$C$35)+H28*(1-Assumptions!$C$36)+H29*(1-Assumptions!$C$37)+H30*(1-Assumptions!$C$38)+H31*(1-Assumptions!$C$39) -> 0 | I33: =I27*(1-Assumptions!$C$35)+I28*(1-Assumptions!$C$36)+I29*(1-Assumptions!$C$37)+I30*(1-Assumptions!$C$38)+I31*(1-Assumptions!$C$39) -> 0 | J33: =J27*(1-Assumptions!$C$35)+J28*(1-Assumptions!$C$36)+J29*(1-Assumptions!$C$37)+J30*(1-Assumptions!$C$38)+J31*(1-Assumptions!$C$39) -> 0 | K33: =K27*(1-Assumptions!$C$35)+K28*(1-Assumptions!$C$36)+K29*(1-Assumptions!$C$37)+K30*(1-Assumptions!$C$38)+K31*(1-Assumptions!$C$39) -> 0 | ... BK33: =BK27*(1-Assumptions!$C$35)+BK28*(1-Assumptions!$C$36)+BK29*(1-Assumptions!$C$37)+BK30*(1-Assumptions!$C$38)+BK31*(1-Assumptions!$C$39) -> 117.98312
A34: pro_merchants | B34: Pro merchants | D34: =D27*Assumptions!$C$35+D28*Assumptions!$C$36+D29*Assumptions!$C$37+D30*Assumptions!$C$38+D31*Assumptions!$C$39 -> 0 | E34: =E27*Assumptions!$C$35+E28*Assumptions!$C$36+E29*Assumptions!$C$37+E30*Assumptions!$C$38+E31*Assumptions!$C$39 -> 0 | F34: =F27*Assumptions!$C$35+F28*Assumptions!$C$36+F29*Assumptions!$C$37+F30*Assumptions!$C$38+F31*Assumptions!$C$39 -> 0 | G34: =G27*Assumptions!$C$35+G28*Assumptions!$C$36+G29*Assumptions!$C$37+G30*Assumptions!$C$38+G31*Assumptions!$C$39 -> 0 | H34: =H27*Assumptions!$C$35+H28*Assumptions!$C$36+H29*Assumptions!$C$37+H30*Assumptions!$C$38+H31*Assumptions!$C$39 -> 0 | I34: =I27*Assumptions!$C$35+I28*Assumptions!$C$36+I29*Assumptions!$C$37+I30*Assumptions!$C$38+I31*Assumptions!$C$39 -> 0 | J34: =J27*Assumptions!$C$35+J28*Assumptions!$C$36+J29*Assumptions!$C$37+J30*Assumptions!$C$38+J31*Assumptions!$C$39 -> 0 | K34: =K27*Assumptions!$C$35+K28*Assumptions!$C$36+K29*Assumptions!$C$37+K30*Assumptions!$C$38+K31*Assumptions!$C$39 -> 0 | ... BK34: =BK27*Assumptions!$C$35+BK28*Assumptions!$C$36+BK29*Assumptions!$C$37+BK30*Assumptions!$C$38+BK31*Assumptions!$C$39 -> 68.296764
A35: new_conversions | B35: New paid conversions | D35: =MAX(0,D32-C32*(1-Assumptions!$C$41)) -> 0 | E35: =MAX(0,E32-D32*(1-Assumptions!$C$41)) -> 0 | F35: =MAX(0,F32-E32*(1-Assumptions!$C$41)) -> 0 | G35: =MAX(0,G32-F32*(1-Assumptions!$C$41)) -> 0 | H35: =MAX(0,H32-G32*(1-Assumptions!$C$41)) -> 0 | I35: =MAX(0,I32-H32*(1-Assumptions!$C$41)) -> 0 | J35: =MAX(0,J32-I32*(1-Assumptions!$C$41)) -> 0 | K35: =MAX(0,K32-J32*(1-Assumptions!$C$41)) -> 0 | ... BK35: =MAX(0,BK32-BJ32*(1-Assumptions!$C$41)) -> 10.842996
B36: Revenue (CAD)
A37: rev_plus | B37: Plus subscriptions | D37: =D33*Assumptions!$C$42 -> 0 | E37: =E33*Assumptions!$C$42 -> 0 | F37: =F33*Assumptions!$C$42 -> 0 | G37: =G33*Assumptions!$C$42 -> 0 | H37: =H33*Assumptions!$C$42 -> 0 | I37: =I33*Assumptions!$C$42 -> 0 | J37: =J33*Assumptions!$C$42 -> 0 | K37: =K33*Assumptions!$C$42 -> 0 | ... BK37: =BK33*Assumptions!$C$42 -> 4601.3416
A38: rev_pro | B38: Pro subscriptions | D38: =D34*Assumptions!$C$43 -> 0 | E38: =E34*Assumptions!$C$43 -> 0 | F38: =F34*Assumptions!$C$43 -> 0 | G38: =G34*Assumptions!$C$43 -> 0 | H38: =H34*Assumptions!$C$43 -> 0 | I38: =I34*Assumptions!$C$43 -> 0 | J38: =J34*Assumptions!$C$43 -> 0 | K38: =K34*Assumptions!$C$43 -> 0 | ... BK38: =BK34*Assumptions!$C$43 -> 5395.4443
A39: gmv_in_app | B39: In-app payment volume (GMV) | D39: =(D33*Assumptions!$C$46+D34*Assumptions!$C$47)*Assumptions!$C$45 -> 0 | E39: =(E33*Assumptions!$C$46+E34*Assumptions!$C$47)*Assumptions!$C$45 -> 0 | F39: =(F33*Assumptions!$C$46+F34*Assumptions!$C$47)*Assumptions!$C$45 -> 0 | G39: =(G33*Assumptions!$C$46+G34*Assumptions!$C$47)*Assumptions!$C$45 -> 0 | H39: =(H33*Assumptions!$C$46+H34*Assumptions!$C$47)*Assumptions!$C$45 -> 0 | I39: =(I33*Assumptions!$C$46+I34*Assumptions!$C$47)*Assumptions!$C$45 -> 0 | J39: =(J33*Assumptions!$C$46+J34*Assumptions!$C$47)*Assumptions!$C$45 -> 0 | K39: =(K33*Assumptions!$C$46+K34*Assumptions!$C$47)*Assumptions!$C$45 -> 0 | ... BK39: =(BK33*Assumptions!$C$46+BK34*Assumptions!$C$47)*Assumptions!$C$45 -> 422843.03
